<?xml version="1.0"?>
<robot name="bot">
    <gazebo>
        <plugin name="gazebo_ros_control" filename="libgazebo_ros_control.so">
            <legacyModeNS>true</legacyModeNS>
        </plugin>
    </gazebo>
<!--links-->

    <link name="base_footprint">
        <origin xyz="0.0 0.0 0.0" rpy="0.0 0.0 0.0"/>
    </link>
    <link name="base_link">
        <visual >
            <origin xyz="0.0 0.0 0.0" rpy="0.0 0.0 1.5707"/>
            <geometry>
                <mesh filename="package://bot_description/models/meshes/body.dae"/>
            </geometry>
        </visual>
        <collision>
            <origin xyz="0.0 0.0 0.0" rpy="0.0 0.0 1.5707"/>
            <geometry>
                <mesh filename="package://bot_description/models/meshes/body.dae"/>
            </geometry>
        </collision>
        <inertial>
            <origin xyz="0.0 0.0 0.0" rpy="0.0 0.0 1.5707"/>
            <mass value="2.78"/>
            <inertia ixx="0.0290046666667" ixy="0.0" ixz="0.0" iyy="0.022153125" iyz="0.0" izz="0.0244697916667"/>
        </inertial>
    </link>
    <link name="imu_link">
        <inertial>
            <origin xyz="0.0 0.0 0.0" rpy="0.0 0.0 0"/>
            <mass value="0.001"/>
            <inertia ixx="0.0000001" ixy="0.000000" ixz="0.000000" iyy="0.00000001" iyz="0.0" izz="0.000000001"/>
        </inertial>
        <visual>
            <origin xyz="0.0 0.0 0.0" rpy="0.0 0.0 0"/>
            <geometry>
                <box size="0.001 0.001 0.001"/>
            </geometry>
        </visual>
        <collision>
            <origin xyz="0.0 0.0 0.0" rpy="0.0 0.0 0"/>
            <geometry>
                <box size="0.001 0.001 0.001"/>
            </geometry>
        </collision>
    </link>
    <link name="gps_link">
        <inertial>
            <origin xyz="0.0 0.0 0.0" rpy="0.0 0.0 0.0"/>
            <mass value="0.001"/>
            <inertia ixx="0.0000001" ixy="0.000000" ixz="0.000000" iyy="0.00000001" iyz="0.0" izz="0.000000001"/>
        </inertial>
        <visual>
            <origin xyz="0.0 0.0 0.0" rpy="0.0 0.0 0"/>
            <geometry>
                <box size="0.001 0.001 0.001"/>
            </geometry>
        </visual>
        <collision>
            <origin xyz="0.0 0.0 0.0" rpy="0.0 0.0 0"/>
            <geometry>
                <box size="0.001 0.001 0.001"/>
            </geometry>
        </collision>
    </link>
    <link name="RFW_link">
        <visual >
            <origin xyz="0.0 0.0 0.0" rpy="0.0 0.0 1.5707"/>
            <geometry>
                <mesh filename="package://bot_description/models/meshes/roue.dae"/>
            </geometry>
        </visual>
        <collision>
            <origin xyz="0.0 0.0 0.0" rpy="0.0 0.0 1.5707"/>
            <geometry>
                <mesh filename="package://bot_description/models/meshes/roue.dae"/>
            </geometry>
        </collision>
        <inertial>
            <origin xyz="0.0 0.0 0.0" rpy="0.0 0.0 1.5707"/>
            <mass value="0.156"/>
            <inertia ixx="0.000211575" ixy="0.0" ixz="0.0" iyy="0.000211575" iyz="0.0" izz="0.00032955"/>
        </inertial>
    </link>
    <link name="LFW_link">
        <visual >
            <origin xyz="0.0 0.0 0.0" rpy="0.0 0.0 1.5707"/>
            <geometry>
                <mesh filename="package://bot_description/models/meshes/roue.dae"/>
            </geometry>
        </visual>
        <collision>
            <origin xyz="0.0 0.0 0.0" rpy="0.0 0.0 1.5707"/>
            <geometry>
                <mesh filename="package://bot_description/models/meshes/roue.dae"/>
            </geometry>
        </collision>
        <inertial>
            <origin xyz="0.0 0.0 0.0" rpy="0.0 0.0 1.5707"/>
            <mass value="0.156"/>
            <inertia ixx="0.000211575" ixy="0.0" ixz="0.0" iyy="0.000211575" iyz="0.0" izz="0.00032955"/>
        </inertial>
    </link>
    <link name="RBW_link">
        <visual >
            <origin xyz="0.0 0.0 0.0" rpy="0.0 0.0 1.5707"/>
            <geometry>
                <mesh filename="package://bot_description/models/meshes/roue.dae"/>
            </geometry>
        </visual>
        <collision>
            <origin xyz="0.0 0.0 0.0" rpy="0.0 0.0 1.5707"/>
            <geometry>
                <mesh filename="package://bot_description/models/meshes/roue.dae"/>
            </geometry>
        </collision>
        <inertial>
            <origin xyz="0.0 0.0 0.0" rpy="0.0 0.0 1.5707"/>
            <mass value="0.156"/>
            <inertia ixx="0.000211575" ixy="0.0" ixz="0.0" iyy="0.000211575" iyz="0.0" izz="0.00032955"/>
        </inertial>
    </link>
    <link name="LBW_link">
        <visual >
            <origin xyz="0.0 0.0 0.0" rpy="0.0 0.0 1.5707"/>
            <geometry>
                <mesh filename="package://bot_description/models/meshes/roue.dae"/>
            </geometry>
        </visual>
        <collision>
            <origin xyz="0.0 0.0 0.0" rpy="0.0 0.0 1.5707"/>
            <geometry>
                <mesh filename="package://bot_description/models/meshes/roue.dae"/>
            </geometry>
        </collision>
        <inertial>
            <origin xyz="0.0 0.0 0.0" rpy="0.0 0.0 1.5707"/>
            <mass value="0.156"/>
            <inertia ixx="0.000211575" ixy="0.0" ixz="0.0" iyy="0.000211575" iyz="0.0" izz="0.00032955"/>
        </inertial>
    </link>
<!--joints-->
    <joint name="base_joint" type="fixed">
        <origin xyz="0.0 0.0 0.0" rpy="0.0 0.0 0"/>
        <parent link="base_footprint"/>
        <child link="base_link"/>
    </joint>
    <joint name="imu_joint" type="fixed">
        <origin xyz="0.0 0.0 0.1" rpy="0.0 0.0 0.0"/>
        <parent link="base_link"/>
        <child link="imu_link"/>
    </joint>
    <joint name="gps_joint" type="fixed">
        <origin xyz="0.05 0.0 0.1" rpy="0.0 0.0 0.0"/>
        <parent link="base_link"/>
        <child link="gps_link"/>
    </joint>
    <joint name="LFW_joint" type="continuous">
        <origin xyz=" 0.0975 0.130 0.0" rpy="0.0 0.0 0.0"/>
        <parent link="base_link"/>
        <child link="RFW_link"/>
        <axis xyz="0.0 1.0 0.0"/>
        <limit effort="100" velocity="100"/> 
    </joint>
    <joint name="LBW_joint" type="continuous">
        <origin xyz=" -0.0975 0.130 0.0" rpy="0.0 0.0 0.0"/>
        <parent link="base_link"/>
        <child link="LFW_link"/>
        <axis xyz="0.0 1.0 0.0"/>
        <limit effort="100" velocity="100"/> 
    </joint>
    <joint name="RBW_joint" type="continuous">
        <origin xyz="-0.0975 -0.137 0.0" rpy="0.0 0.0 0.0"/>
        <parent link="base_link"/>
        <child link="RBW_link"/>
        <axis xyz="0.0 1.0 0.0"/>
        <limit effort="100" velocity="100"/> 
    </joint>
    <joint name="RFW_joint" type="continuous">
        <origin xyz="0.0975 -0.137  0.0" rpy="0.0 0.0 0.0"/>
        <parent link="base_link"/>
        <child link="LBW_link"/>
        <axis xyz="0.0 1.0 0.0"/>
        <limit effort="100" velocity="100"/> 
    </joint>


<!--gazebo plugins-->
    <gazebo reference="RFW_link">
        <mu1>20000000000.0</mu1>
	    <mu2>20000000000.0</mu2>
	    <kp>1000000.0</kp>
	    <kd>1.0</kd>
	    <material>Gazebo/Black</material>
	</gazebo>
    <gazebo reference="LFW_link">
        <mu1>20000000000.0</mu1>
	    <mu2>20000000000.0</mu2>
	    <kp>1000000.0</kp>
	    <kd>1.0</kd>
	    <material>Gazebo/Black</material>
	</gazebo>
    <gazebo reference="RBW_link">
        <mu1>20000000000.0</mu1>
	    <mu2>20000000000.0</mu2>
	    <kp>1000000.0</kp>
	    <kd>1.0</kd>
	    <material>Gazebo/Black</material>
	</gazebo>
    <gazebo reference="LBW_link">
        <mu1>20000000000.0</mu1>
	    <mu2>20000000000.0</mu2>
	    <kp>1000000.0</kp>
	    <kd>1.0</kd>
	    <material>Gazebo/Black</material>
	</gazebo>
    <gazebo reference="base_link">
	    <material>Gazebo/Orange</material>
	</gazebo>

    <!--<gazebo>
    <plugin name="imu_plugin" filename="libgazebo_ros_imu.so">
      <alwaysOn>true</alwaysOn>
      <bodyName>imu_link</bodyName>
      <topicName>imu</topicName>
      <serviceName>imu_service</serviceName>
      <gaussianNoise>0.0</gaussianNoise>
      <updateRate>20.0</updateRate>
    </plugin>
  </gazebo>-->
    <gazebo reference="imu_link">
    <gravity>true</gravity>
    <sensor name="imu_sensor" type="imu">
      <always_on>true</always_on>
      <update_rate>30.0</update_rate>
      <visualize>true</visualize>
      <topic>__default_topic__</topic>
      <plugin filename="libgazebo_ros_imu_sensor.so" name="imu_plugin">
        <topicName>imu</topicName>
        <bodyName>imu_link</bodyName>
        <updateRateHZ>10.0</updateRateHZ>
        <gaussianNoise>0.0</gaussianNoise>
        <xyzOffset>0 0 0</xyzOffset>
        <rpyOffset>0 0 0</rpyOffset>
        <frameName>imu_link</frameName>
        <initialOrientationAsReference>false</initialOrientationAsReference>
      </plugin>
      <pose>0 0 0 0 0 0</pose>
    </sensor>
  </gazebo>
    <gazebo>
        <plugin name="skid_steer_drive_controller" filename="libgazebo_ros_skid_steer_drive.so">
            <updateRate>100.0</updateRate>
            <leftFrontJoint>LFW_joint</leftFrontJoint>
            <rightFrontJoint>RFW_joint</rightFrontJoint>
            <leftRearJoint>LBW_joint</leftRearJoint>
            <rightRearJoint>RBW_joint</rightRearJoint>
            <wheelSeparation>0.21</wheelSeparation>
            <wheelDiameter>0.13</wheelDiameter>
            <robotBaseFrame>base_footprint</robotBaseFrame>
            <torque>20</torque>
            <topicName>cmd_vel</topicName>
            <broadcastTF>true</broadcastTF>
        </plugin>
    </gazebo>
    <gazebo>
        <plugin name="gps_controller" filename="libhector_gazebo_ros_gps.so">
            <alwayson>true</alwayson>
            <updaterate>1.0</updaterate>
            <bodyname>gps_link</bodyname>
            <frameId>gps_link</frameId>
            <topicname>/fix</topicname>
            <velocitytopicname>/fix_velocity</velocitytopicname>
            <drift>0.0 0.0 0.0</drift>
            <gaussiannoise>0.1 0.1 0.1</gaussiannoise>
            <velocitydrift>0 0 0</velocitydrift>
            <velocitygaussiannoise>0.1 0.1 0.1</velocitygaussiannoise>
        </plugin>
    </gazebo>
<!--transmissions-->
    <transmission name="RFW_transmission">
        <type>transmission_interface/SimpleTransmission</type>
        <joint name="RFW_joint">
            <hardwareInterface>hardware_interface/EffortJointInterface</hardwareInterface>  
        </joint>
        <actuator name="RFW_actuator">
            <mechanicalReduction>7</mechanicalReduction>
            <hardwareInterface>hardware_interface/EffortJointInterface</hardwareInterface>
        </actuator>
    </transmission>

    <transmission name="LFW_transmission">
        <type>transmission_interface/SimpleTransmission</type>
        <joint name="LFW_joint">
            <hardwareInterface>hardware_interface/EffortJointInterface</hardwareInterface>  
        </joint>
        <actuator name="LFW_actuator">
            <mechanicalReduction>7</mechanicalReduction>
            <hardwareInterface>hardware_interface/EffortJointInterface</hardwareInterface>
        </actuator>
    </transmission>

    <transmission name="RBW_transmission">
        <type>transmission_interface/SimpleTransmission</type>
        <joint name="RBW_joint">
            <hardwareInterface>hardware_interface/EffortJointInterface</hardwareInterface>  
        </joint>
        <actuator name="RBW_actuator">
            <mechanicalReduction>7</mechanicalReduction>
            <hardwareInterface>hardware_interface/EffortJointInterface</hardwareInterface>
        </actuator>
    </transmission>

    <transmission name="LBW_transmission">
        <type>transmission_interface/SimpleTransmission</type>
        <joint name="LBW_joint">
            <hardwareInterface>hardware_interface/EffortJointInterface</hardwareInterface>  
        </joint>
        <actuator name="LBW_actuator">
            <mechanicalReduction>7</mechanicalReduction>
            <hardwareInterface>hardware_interface/EffortJointInterface</hardwareInterface>
        </actuator>
    </transmission>
    

</robot>
